2024-11-02 23:26:12,775 (__init__.py:1241 MainThread) ERROR - TeleBot: "Threaded polling exception: A request to the Telegram API was unsuccessful. Error code: 502. Description: Bad Gateway"
2024-11-02 23:26:12,776 (__init__.py:1243 MainThread) ERROR - TeleBot: "Exception traceback:
Traceback (most recent call last):
  File "/root/Amaar_bott/venv/lib/python3.12/site-packages/telebot/__init__.py", line 1234, in __threaded_polling
    polling_thread.raise_exceptions()
  File "/root/Amaar_bott/venv/lib/python3.12/site-packages/telebot/util.py", line 111, in raise_exceptions
    raise self.exception_info
  File "/root/Amaar_bott/venv/lib/python3.12/site-packages/telebot/util.py", line 93, in run
    task(*args, **kwargs)
  File "/root/Amaar_bott/venv/lib/python3.12/site-packages/telebot/__init__.py", line 688, in __retrieve_updates
    updates = self.get_updates(offset=(self.last_update_id + 1),
             ^^^^^^^^^^^^^^^^^^^^^^^^^^^^^^^^^^^^^^^^^^^^^^^^^^
  File "/root/Amaar_bott/venv/lib/python3.12/site-packages/telebot/__init__.py", line 660, in get_updates
    json_updates = apihelper.get_updates(
                   ^^^^^^^^^^^^^^^^^^^^^^
  File "/root/Amaar_bott/venv/lib/python3.12/site-packages/telebot/apihelper.py", line 330, in get_updates
    return _make_request(token, method_url, params=payload)
           ^^^^^^^^^^^^^^^^^^^^^^^^^^^^^^^^^^^^^^^^^^^^^^^^
  File "/root/Amaar_bott/venv/lib/python3.12/site-packages/telebot/apihelper.py", line 168, in _make_request
    json_result = _check_result(method_name, result)
                  ^^^^^^^^^^^^^^^^^^^^^^^^^^^^^^^^^^
  File "/root/Amaar_bott/venv/lib/python3.12/site-packages/telebot/apihelper.py", line 195, in _check_result
    raise ApiTelegramException(method_name, result, result_json)
telebot.apihelper.ApiTelegramException: A request to the Telegram API was unsuccessful. Error code: 502. Description: Bad Gateway
"
2024-11-02 23:26:13,045 (__init__.py:1241 MainThread) ERROR - TeleBot: "Threaded polling exception: A request to the Telegram API was unsuccessful. Error code: 502. Description: Bad Gateway"
2024-11-02 23:26:13,046 (__init__.py:1243 MainThread) ERROR - TeleBot: "Exception traceback:
Traceback (most recent call last):
  File "/root/Amaar_bott/venv/lib/python3.12/site-packages/telebot/__init__.py", line 1234, in __threaded_polling
    polling_thread.raise_exceptions()
  File "/root/Amaar_bott/venv/lib/python3.12/site-packages/telebot/util.py", line 111, in raise_exceptions
    raise self.exception_info
  File "/root/Amaar_bott/venv/lib/python3.12/site-packages/telebot/util.py", line 93, in run
    task(*args, **kwargs)
  File "/root/Amaar_bott/venv/lib/python3.12/site-packages/telebot/__init__.py", line 688, in __retrieve_updates
    updates = self.get_updates(offset=(self.last_update_id + 1),
             ^^^^^^^^^^^^^^^^^^^^^^^^^^^^^^^^^^^^^^^^^^^^^^^^^^
  File "/root/Amaar_bott/venv/lib/python3.12/site-packages/telebot/__init__.py", line 660, in get_updates
    json_updates = apihelper.get_updates(
                   ^^^^^^^^^^^^^^^^^^^^^^
  File "/root/Amaar_bott/venv/lib/python3.12/site-packages/telebot/apihelper.py", line 330, in get_updates
    return _make_request(token, method_url, params=payload)
           ^^^^^^^^^^^^^^^^^^^^^^^^^^^^^^^^^^^^^^^^^^^^^^^^
  File "/root/Amaar_bott/venv/lib/python3.12/site-packages/telebot/apihelper.py", line 168, in _make_request
    json_result = _check_result(method_name, result)
                  ^^^^^^^^^^^^^^^^^^^^^^^^^^^^^^^^^^
  File "/root/Amaar_bott/venv/lib/python3.12/site-packages/telebot/apihelper.py", line 195, in _check_result
    raise ApiTelegramException(method_name, result, result_json)
telebot.apihelper.ApiTelegramException: A request to the Telegram API was unsuccessful. Error code: 502. Description: Bad Gateway
"
2024-11-02 23:26:13,562 (__init__.py:1241 MainThread) ERROR - TeleBot: "Threaded polling exception: A request to the Telegram API was unsuccessful. Error code: 502. Description: Bad Gateway"
2024-11-02 23:26:13,562 (__init__.py:1243 MainThread) ERROR - TeleBot: "Exception traceback:
Traceback (most recent call last):
  File "/root/Amaar_bott/venv/lib/python3.12/site-packages/telebot/__init__.py", line 1234, in __threaded_polling
    polling_thread.raise_exceptions()
  File "/root/Amaar_bott/venv/lib/python3.12/site-packages/telebot/util.py", line 111, in raise_exceptions
    raise self.exception_info
  File "/root/Amaar_bott/venv/lib/python3.12/site-packages/telebot/util.py", line 93, in run
    task(*args, **kwargs)
  File "/root/Amaar_bott/venv/lib/python3.12/site-packages/telebot/__init__.py", line 688, in __retrieve_updates
    updates = self.get_updates(offset=(self.last_update_id + 1),
             ^^^^^^^^^^^^^^^^^^^^^^^^^^^^^^^^^^^^^^^^^^^^^^^^^^
  File "/root/Amaar_bott/venv/lib/python3.12/site-packages/telebot/__init__.py", line 660, in get_updates
    json_updates = apihelper.get_updates(
                   ^^^^^^^^^^^^^^^^^^^^^^
  File "/root/Amaar_bott/venv/lib/python3.12/site-packages/telebot/apihelper.py", line 330, in get_updates
    return _make_request(token, method_url, params=payload)
           ^^^^^^^^^^^^^^^^^^^^^^^^^^^^^^^^^^^^^^^^^^^^^^^^
  File "/root/Amaar_bott/venv/lib/python3.12/site-packages/telebot/apihelper.py", line 168, in _make_request
    json_result = _check_result(method_name, result)
                  ^^^^^^^^^^^^^^^^^^^^^^^^^^^^^^^^^^
  File "/root/Amaar_bott/venv/lib/python3.12/site-packages/telebot/apihelper.py", line 195, in _check_result
    raise ApiTelegramException(method_name, result, result_json)
telebot.apihelper.ApiTelegramException: A request to the Telegram API was unsuccessful. Error code: 502. Description: Bad Gateway
"
2024-11-02 23:26:14,589 (__init__.py:1241 MainThread) ERROR - TeleBot: "Threaded polling exception: A request to the Telegram API was unsuccessful. Error code: 502. Description: Bad Gateway"
2024-11-02 23:26:14,590 (__init__.py:1243 MainThread) ERROR - TeleBot: "Exception traceback:
Traceback (most recent call last):
  File "/root/Amaar_bott/venv/lib/python3.12/site-packages/telebot/__init__.py", line 1234, in __threaded_polling
    polling_thread.raise_exceptions()
  File "/root/Amaar_bott/venv/lib/python3.12/site-packages/telebot/util.py", line 111, in raise_exceptions
    raise self.exception_info
  File "/root/Amaar_bott/venv/lib/python3.12/site-packages/telebot/util.py", line 93, in run
    task(*args, **kwargs)
  File "/root/Amaar_bott/venv/lib/python3.12/site-packages/telebot/__init__.py", line 688, in __retrieve_updates
    updates = self.get_updates(offset=(self.last_update_id + 1),
             ^^^^^^^^^^^^^^^^^^^^^^^^^^^^^^^^^^^^^^^^^^^^^^^^^^
  File "/root/Amaar_bott/venv/lib/python3.12/site-packages/telebot/__init__.py", line 660, in get_updates
    json_updates = apihelper.get_updates(
                   ^^^^^^^^^^^^^^^^^^^^^^
  File "/root/Amaar_bott/venv/lib/python3.12/site-packages/telebot/apihelper.py", line 330, in get_updates
    return _make_request(token, method_url, params=payload)
           ^^^^^^^^^^^^^^^^^^^^^^^^^^^^^^^^^^^^^^^^^^^^^^^^
  File "/root/Amaar_bott/venv/lib/python3.12/site-packages/telebot/apihelper.py", line 168, in _make_request
    json_result = _check_result(method_name, result)
                  ^^^^^^^^^^^^^^^^^^^^^^^^^^^^^^^^^^
  File "/root/Amaar_bott/venv/lib/python3.12/site-packages/telebot/apihelper.py", line 195, in _check_result
    raise ApiTelegramException(method_name, result, result_json)
telebot.apihelper.ApiTelegramException: A request to the Telegram API was unsuccessful. Error code: 502. Description: Bad Gateway
"
2024-11-02 23:26:41,605 (__init__.py:1115 MainThread) ERROR - TeleBot: "Infinity polling exception: HTTPSConnectionPool(host='api.telegram.org', port=443): Read timed out. (read timeout=25)"
2024-11-02 23:26:41,608 (__init__.py:1117 MainThread) ERROR - TeleBot: "Exception traceback:
Traceback (most recent call last):
  File "/root/Amaar_bott/venv/lib/python3.12/site-packages/urllib3/connectionpool.py", line 536, in _make_request
    response = conn.getresponse()
               ^^^^^^^^^^^^^^^^^^
  File "/root/Amaar_bott/venv/lib/python3.12/site-packages/urllib3/connection.py", line 507, in getresponse
    httplib_response = super().getresponse()
                       ^^^^^^^^^^^^^^^^^^^^^
  File "/usr/lib/python3.12/http/client.py", line 1428, in getresponse
    response.begin()
  File "/usr/lib/python3.12/http/client.py", line 331, in begin
    version, status, reason = self._read_status()
                              ^^^^^^^^^^^^^^^^^^^
  File "/usr/lib/python3.12/http/client.py", line 292, in _read_status
    line = str(self.fp.readline(_MAXLINE + 1), "iso-8859-1")
               ^^^^^^^^^^^^^^^^^^^^^^^^^^^^^^
  File "/usr/lib/python3.12/socket.py", line 720, in readinto
    return self._sock.recv_into(b)
           ^^^^^^^^^^^^^^^^^^^^^^^
  File "/usr/lib/python3.12/ssl.py", line 1251, in recv_into
    return self.read(nbytes, buffer)
           ^^^^^^^^^^^^^^^^^^^^^^^^^
  File "/usr/lib/python3.12/ssl.py", line 1103, in read
    return self._sslobj.read(len, buffer)
           ^^^^^^^^^^^^^^^^^^^^^^^^^^^^^^
TimeoutError: The read operation timed out

The above exception was the direct cause of the following exception:

Traceback (most recent call last):
  File "/root/Amaar_bott/venv/lib/python3.12/site-packages/requests/adapters.py", line 667, in send
    resp = conn.urlopen(
           ^^^^^^^^^^^^^
  File "/root/Amaar_bott/venv/lib/python3.12/site-packages/urllib3/connectionpool.py", line 843, in urlopen
    retries = retries.increment(
              ^^^^^^^^^^^^^^^^^^
  File "/root/Amaar_bott/venv/lib/python3.12/site-packages/urllib3/util/retry.py", line 474, in increment
    raise reraise(type(error), error, _stacktrace)
          ^^^^^^^^^^^^^^^^^^^^^^^^^^^^^^^^^^^^^^^^
  File "/root/Amaar_bott/venv/lib/python3.12/site-packages/urllib3/util/util.py", line 39, in reraise
    raise value
  File "/root/Amaar_bott/venv/lib/python3.12/site-packages/urllib3/connectionpool.py", line 789, in urlopen
    response = self._make_request(
               ^^^^^^^^^^^^^^^^^^^
  File "/root/Amaar_bott/venv/lib/python3.12/site-packages/urllib3/connectionpool.py", line 538, in _make_request
    self._raise_timeout(err=e, url=url, timeout_value=read_timeout)
  File "/root/Amaar_bott/venv/lib/python3.12/site-packages/urllib3/connectionpool.py", line 369, in _raise_timeout
    raise ReadTimeoutError(
urllib3.exceptions.ReadTimeoutError: HTTPSConnectionPool(host='api.telegram.org', port=443): Read timed out. (read timeout=25)

During handling of the above exception, another exception occurred:

Traceback (most recent call last):
  File "/root/Amaar_bott/venv/lib/python3.12/site-packages/telebot/__init__.py", line 1110, in infinity_polling
    self.polling(non_stop=True, timeout=timeout, long_polling_timeout=long_polling_timeout,
  File "/root/Amaar_bott/venv/lib/python3.12/site-packages/telebot/__init__.py", line 1198, in polling
    self.__threaded_polling(non_stop=non_stop, interval=interval, timeout=timeout, long_polling_timeout=long_polling_timeout,
  File "/root/Amaar_bott/venv/lib/python3.12/site-packages/telebot/__init__.py", line 1273, in __threaded_polling
    raise e
  File "/root/Amaar_bott/venv/lib/python3.12/site-packages/telebot/__init__.py", line 1234, in __threaded_polling
    polling_thread.raise_exceptions()
  File "/root/Amaar_bott/venv/lib/python3.12/site-packages/telebot/util.py", line 111, in raise_exceptions
    raise self.exception_info
  File "/root/Amaar_bott/venv/lib/python3.12/site-packages/telebot/util.py", line 93, in run
    task(*args, **kwargs)
  File "/root/Amaar_bott/venv/lib/python3.12/site-packages/telebot/__init__.py", line 688, in __retrieve_updates
    updates = self.get_updates(offset=(self.last_update_id + 1),
             ^^^^^^^^^^^^^^^^^^^^^^^^^^^^^^^^^^^^^^^^^^^^^^^^^^
  File "/root/Amaar_bott/venv/lib/python3.12/site-packages/telebot/__init__.py", line 660, in get_updates
    json_updates = apihelper.get_updates(
                   ^^^^^^^^^^^^^^^^^^^^^^
  File "/root/Amaar_bott/venv/lib/python3.12/site-packages/telebot/apihelper.py", line 330, in get_updates
    return _make_request(token, method_url, params=payload)
           ^^^^^^^^^^^^^^^^^^^^^^^^^^^^^^^^^^^^^^^^^^^^^^^^
  File "/root/Amaar_bott/venv/lib/python3.12/site-packages/telebot/apihelper.py", line 162, in _make_request
    result = _get_req_session().request(
             ^^^^^^^^^^^^^^^^^^^^^^^^^^^
  File "/root/Amaar_bott/venv/lib/python3.12/site-packages/requests/sessions.py", line 589, in request
    resp = self.send(prep, **send_kwargs)
           ^^^^^^^^^^^^^^^^^^^^^^^^^^^^^^
  File "/root/Amaar_bott/venv/lib/python3.12/site-packages/requests/sessions.py", line 703, in send
    r = adapter.send(request, **kwargs)
        ^^^^^^^^^^^^^^^^^^^^^^^^^^^^^^^
  File "/root/Amaar_bott/venv/lib/python3.12/site-packages/requests/adapters.py", line 713, in send
    raise ReadTimeout(e, request=request)
requests.exceptions.ReadTimeout: HTTPSConnectionPool(host='api.telegram.org', port=443): Read timed out. (read timeout=25)
"
2024-11-02 23:27:09,659 (__init__.py:1115 MainThread) ERROR - TeleBot: "Infinity polling exception: HTTPSConnectionPool(host='api.telegram.org', port=443): Read timed out. (read timeout=25)"
2024-11-02 23:27:09,663 (__init__.py:1117 MainThread) ERROR - TeleBot: "Exception traceback:
Traceback (most recent call last):
  File "/root/Amaar_bott/venv/lib/python3.12/site-packages/urllib3/connectionpool.py", line 536, in _make_request
    response = conn.getresponse()
               ^^^^^^^^^^^^^^^^^^
  File "/root/Amaar_bott/venv/lib/python3.12/site-packages/urllib3/connection.py", line 507, in getresponse
    httplib_response = super().getresponse()
                       ^^^^^^^^^^^^^^^^^^^^^
  File "/usr/lib/python3.12/http/client.py", line 1428, in getresponse
    response.begin()
  File "/usr/lib/python3.12/http/client.py", line 331, in begin
    version, status, reason = self._read_status()
                              ^^^^^^^^^^^^^^^^^^^
  File "/usr/lib/python3.12/http/client.py", line 292, in _read_status
    line = str(self.fp.readline(_MAXLINE + 1), "iso-8859-1")
               ^^^^^^^^^^^^^^^^^^^^^^^^^^^^^^
  File "/usr/lib/python3.12/socket.py", line 720, in readinto
    return self._sock.recv_into(b)
           ^^^^^^^^^^^^^^^^^^^^^^^
  File "/usr/lib/python3.12/ssl.py", line 1251, in recv_into
    return self.read(nbytes, buffer)
           ^^^^^^^^^^^^^^^^^^^^^^^^^
  File "/usr/lib/python3.12/ssl.py", line 1103, in read
    return self._sslobj.read(len, buffer)
           ^^^^^^^^^^^^^^^^^^^^^^^^^^^^^^
TimeoutError: The read operation timed out

The above exception was the direct cause of the following exception:

Traceback (most recent call last):
  File "/root/Amaar_bott/venv/lib/python3.12/site-packages/requests/adapters.py", line 667, in send
    resp = conn.urlopen(
           ^^^^^^^^^^^^^
  File "/root/Amaar_bott/venv/lib/python3.12/site-packages/urllib3/connectionpool.py", line 843, in urlopen
    retries = retries.increment(
              ^^^^^^^^^^^^^^^^^^
  File "/root/Amaar_bott/venv/lib/python3.12/site-packages/urllib3/util/retry.py", line 474, in increment
    raise reraise(type(error), error, _stacktrace)
          ^^^^^^^^^^^^^^^^^^^^^^^^^^^^^^^^^^^^^^^^
  File "/root/Amaar_bott/venv/lib/python3.12/site-packages/urllib3/util/util.py", line 39, in reraise
    raise value
  File "/root/Amaar_bott/venv/lib/python3.12/site-packages/urllib3/connectionpool.py", line 789, in urlopen
    response = self._make_request(
               ^^^^^^^^^^^^^^^^^^^
  File "/root/Amaar_bott/venv/lib/python3.12/site-packages/urllib3/connectionpool.py", line 538, in _make_request
    self._raise_timeout(err=e, url=url, timeout_value=read_timeout)
  File "/root/Amaar_bott/venv/lib/python3.12/site-packages/urllib3/connectionpool.py", line 369, in _raise_timeout
    raise ReadTimeoutError(
urllib3.exceptions.ReadTimeoutError: HTTPSConnectionPool(host='api.telegram.org', port=443): Read timed out. (read timeout=25)

During handling of the above exception, another exception occurred:

Traceback (most recent call last):
  File "/root/Amaar_bott/venv/lib/python3.12/site-packages/telebot/__init__.py", line 1110, in infinity_polling
    self.polling(non_stop=True, timeout=timeout, long_polling_timeout=long_polling_timeout,
  File "/root/Amaar_bott/venv/lib/python3.12/site-packages/telebot/__init__.py", line 1198, in polling
    self.__threaded_polling(non_stop=non_stop, interval=interval, timeout=timeout, long_polling_timeout=long_polling_timeout,
  File "/root/Amaar_bott/venv/lib/python3.12/site-packages/telebot/__init__.py", line 1273, in __threaded_polling
    raise e
  File "/root/Amaar_bott/venv/lib/python3.12/site-packages/telebot/__init__.py", line 1234, in __threaded_polling
    polling_thread.raise_exceptions()
  File "/root/Amaar_bott/venv/lib/python3.12/site-packages/telebot/util.py", line 111, in raise_exceptions
    raise self.exception_info
  File "/root/Amaar_bott/venv/lib/python3.12/site-packages/telebot/util.py", line 93, in run
    task(*args, **kwargs)
  File "/root/Amaar_bott/venv/lib/python3.12/site-packages/telebot/__init__.py", line 688, in __retrieve_updates
    updates = self.get_updates(offset=(self.last_update_id + 1),
             ^^^^^^^^^^^^^^^^^^^^^^^^^^^^^^^^^^^^^^^^^^^^^^^^^^
  File "/root/Amaar_bott/venv/lib/python3.12/site-packages/telebot/__init__.py", line 660, in get_updates
    json_updates = apihelper.get_updates(
                   ^^^^^^^^^^^^^^^^^^^^^^
  File "/root/Amaar_bott/venv/lib/python3.12/site-packages/telebot/apihelper.py", line 330, in get_updates
    return _make_request(token, method_url, params=payload)
           ^^^^^^^^^^^^^^^^^^^^^^^^^^^^^^^^^^^^^^^^^^^^^^^^
  File "/root/Amaar_bott/venv/lib/python3.12/site-packages/telebot/apihelper.py", line 162, in _make_request
    result = _get_req_session().request(
             ^^^^^^^^^^^^^^^^^^^^^^^^^^^
  File "/root/Amaar_bott/venv/lib/python3.12/site-packages/requests/sessions.py", line 589, in request
    resp = self.send(prep, **send_kwargs)
           ^^^^^^^^^^^^^^^^^^^^^^^^^^^^^^
  File "/root/Amaar_bott/venv/lib/python3.12/site-packages/requests/sessions.py", line 703, in send
    r = adapter.send(request, **kwargs)
        ^^^^^^^^^^^^^^^^^^^^^^^^^^^^^^^
  File "/root/Amaar_bott/venv/lib/python3.12/site-packages/requests/adapters.py", line 713, in send
    raise ReadTimeout(e, request=request)
requests.exceptions.ReadTimeout: HTTPSConnectionPool(host='api.telegram.org', port=443): Read timed out. (read timeout=25)
"
2024-11-02 23:27:37,707 (__init__.py:1115 MainThread) ERROR - TeleBot: "Infinity polling exception: HTTPSConnectionPool(host='api.telegram.org', port=443): Read timed out. (read timeout=25)"
2024-11-02 23:27:37,709 (__init__.py:1117 MainThread) ERROR - TeleBot: "Exception traceback:
Traceback (most recent call last):
  File "/root/Amaar_bott/venv/lib/python3.12/site-packages/urllib3/connectionpool.py", line 536, in _make_request
    response = conn.getresponse()
               ^^^^^^^^^^^^^^^^^^
  File "/root/Amaar_bott/venv/lib/python3.12/site-packages/urllib3/connection.py", line 507, in getresponse
    httplib_response = super().getresponse()
                       ^^^^^^^^^^^^^^^^^^^^^
  File "/usr/lib/python3.12/http/client.py", line 1428, in getresponse
    response.begin()
  File "/usr/lib/python3.12/http/client.py", line 331, in begin
    version, status, reason = self._read_status()
                              ^^^^^^^^^^^^^^^^^^^
  File "/usr/lib/python3.12/http/client.py", line 292, in _read_status
    line = str(self.fp.readline(_MAXLINE + 1), "iso-8859-1")
               ^^^^^^^^^^^^^^^^^^^^^^^^^^^^^^
  File "/usr/lib/python3.12/socket.py", line 720, in readinto
    return self._sock.recv_into(b)
           ^^^^^^^^^^^^^^^^^^^^^^^
  File "/usr/lib/python3.12/ssl.py", line 1251, in recv_into
    return self.read(nbytes, buffer)
           ^^^^^^^^^^^^^^^^^^^^^^^^^
  File "/usr/lib/python3.12/ssl.py", line 1103, in read
    return self._sslobj.read(len, buffer)
           ^^^^^^^^^^^^^^^^^^^^^^^^^^^^^^
TimeoutError: The read operation timed out

The above exception was the direct cause of the following exception:

Traceback (most recent call last):
  File "/root/Amaar_bott/venv/lib/python3.12/site-packages/requests/adapters.py", line 667, in send
    resp = conn.urlopen(
           ^^^^^^^^^^^^^
  File "/root/Amaar_bott/venv/lib/python3.12/site-packages/urllib3/connectionpool.py", line 843, in urlopen
    retries = retries.increment(
              ^^^^^^^^^^^^^^^^^^
  File "/root/Amaar_bott/venv/lib/python3.12/site-packages/urllib3/util/retry.py", line 474, in increment
    raise reraise(type(error), error, _stacktrace)
          ^^^^^^^^^^^^^^^^^^^^^^^^^^^^^^^^^^^^^^^^
  File "/root/Amaar_bott/venv/lib/python3.12/site-packages/urllib3/util/util.py", line 39, in reraise
    raise value
  File "/root/Amaar_bott/venv/lib/python3.12/site-packages/urllib3/connectionpool.py", line 789, in urlopen
    response = self._make_request(
               ^^^^^^^^^^^^^^^^^^^
  File "/root/Amaar_bott/venv/lib/python3.12/site-packages/urllib3/connectionpool.py", line 538, in _make_request
    self._raise_timeout(err=e, url=url, timeout_value=read_timeout)
  File "/root/Amaar_bott/venv/lib/python3.12/site-packages/urllib3/connectionpool.py", line 369, in _raise_timeout
    raise ReadTimeoutError(
urllib3.exceptions.ReadTimeoutError: HTTPSConnectionPool(host='api.telegram.org', port=443): Read timed out. (read timeout=25)

During handling of the above exception, another exception occurred:

Traceback (most recent call last):
  File "/root/Amaar_bott/venv/lib/python3.12/site-packages/telebot/__init__.py", line 1110, in infinity_polling
    self.polling(non_stop=True, timeout=timeout, long_polling_timeout=long_polling_timeout,
  File "/root/Amaar_bott/venv/lib/python3.12/site-packages/telebot/__init__.py", line 1198, in polling
    self.__threaded_polling(non_stop=non_stop, interval=interval, timeout=timeout, long_polling_timeout=long_polling_timeout,
  File "/root/Amaar_bott/venv/lib/python3.12/site-packages/telebot/__init__.py", line 1273, in __threaded_polling
    raise e
  File "/root/Amaar_bott/venv/lib/python3.12/site-packages/telebot/__init__.py", line 1234, in __threaded_polling
    polling_thread.raise_exceptions()
  File "/root/Amaar_bott/venv/lib/python3.12/site-packages/telebot/util.py", line 111, in raise_exceptions
    raise self.exception_info
  File "/root/Amaar_bott/venv/lib/python3.12/site-packages/telebot/util.py", line 93, in run
    task(*args, **kwargs)
  File "/root/Amaar_bott/venv/lib/python3.12/site-packages/telebot/__init__.py", line 688, in __retrieve_updates
    updates = self.get_updates(offset=(self.last_update_id + 1),
             ^^^^^^^^^^^^^^^^^^^^^^^^^^^^^^^^^^^^^^^^^^^^^^^^^^
  File "/root/Amaar_bott/venv/lib/python3.12/site-packages/telebot/__init__.py", line 660, in get_updates
    json_updates = apihelper.get_updates(
                   ^^^^^^^^^^^^^^^^^^^^^^
  File "/root/Amaar_bott/venv/lib/python3.12/site-packages/telebot/apihelper.py", line 330, in get_updates
    return _make_request(token, method_url, params=payload)
           ^^^^^^^^^^^^^^^^^^^^^^^^^^^^^^^^^^^^^^^^^^^^^^^^
  File "/root/Amaar_bott/venv/lib/python3.12/site-packages/telebot/apihelper.py", line 162, in _make_request
    result = _get_req_session().request(
             ^^^^^^^^^^^^^^^^^^^^^^^^^^^
  File "/root/Amaar_bott/venv/lib/python3.12/site-packages/requests/sessions.py", line 589, in request
    resp = self.send(prep, **send_kwargs)
           ^^^^^^^^^^^^^^^^^^^^^^^^^^^^^^
  File "/root/Amaar_bott/venv/lib/python3.12/site-packages/requests/sessions.py", line 703, in send
    r = adapter.send(request, **kwargs)
        ^^^^^^^^^^^^^^^^^^^^^^^^^^^^^^^
  File "/root/Amaar_bott/venv/lib/python3.12/site-packages/requests/adapters.py", line 713, in send
    raise ReadTimeout(e, request=request)
requests.exceptions.ReadTimeout: HTTPSConnectionPool(host='api.telegram.org', port=443): Read timed out. (read timeout=25)
"
2024-11-04 13:28:17,008 (__init__.py:1241 MainThread) ERROR - TeleBot: "Threaded polling exception: A request to the Telegram API was unsuccessful. Error code: 409. Description: Conflict: terminated by other getUpdates request; make sure that only one bot instance is running"
2024-11-04 13:28:17,009 (__init__.py:1243 MainThread) ERROR - TeleBot: "Exception traceback:
Traceback (most recent call last):
  File "/root/Amaar_bott/venv/lib/python3.12/site-packages/telebot/__init__.py", line 1234, in __threaded_polling
    polling_thread.raise_exceptions()
  File "/root/Amaar_bott/venv/lib/python3.12/site-packages/telebot/util.py", line 111, in raise_exceptions
    raise self.exception_info
  File "/root/Amaar_bott/venv/lib/python3.12/site-packages/telebot/util.py", line 93, in run
    task(*args, **kwargs)
  File "/root/Amaar_bott/venv/lib/python3.12/site-packages/telebot/__init__.py", line 688, in __retrieve_updates
    updates = self.get_updates(offset=(self.last_update_id + 1),
             ^^^^^^^^^^^^^^^^^^^^^^^^^^^^^^^^^^^^^^^^^^^^^^^^^^
  File "/root/Amaar_bott/venv/lib/python3.12/site-packages/telebot/__init__.py", line 660, in get_updates
    json_updates = apihelper.get_updates(
                   ^^^^^^^^^^^^^^^^^^^^^^
  File "/root/Amaar_bott/venv/lib/python3.12/site-packages/telebot/apihelper.py", line 330, in get_updates
    return _make_request(token, method_url, params=payload)
           ^^^^^^^^^^^^^^^^^^^^^^^^^^^^^^^^^^^^^^^^^^^^^^^^
  File "/root/Amaar_bott/venv/lib/python3.12/site-packages/telebot/apihelper.py", line 168, in _make_request
    json_result = _check_result(method_name, result)
                  ^^^^^^^^^^^^^^^^^^^^^^^^^^^^^^^^^^
  File "/root/Amaar_bott/venv/lib/python3.12/site-packages/telebot/apihelper.py", line 195, in _check_result
    raise ApiTelegramException(method_name, result, result_json)
telebot.apihelper.ApiTelegramException: A request to the Telegram API was unsuccessful. Error code: 409. Description: Conflict: terminated by other getUpdates request; make sure that only one bot instance is running
"
2024-11-04 13:28:20,764 (__init__.py:1241 MainThread) ERROR - TeleBot: "Threaded polling exception: A request to the Telegram API was unsuccessful. Error code: 409. Description: Conflict: terminated by other getUpdates request; make sure that only one bot instance is running"
2024-11-04 13:28:20,765 (__init__.py:1243 MainThread) ERROR - TeleBot: "Exception traceback:
Traceback (most recent call last):
  File "/root/Amaar_bott/venv/lib/python3.12/site-packages/telebot/__init__.py", line 1234, in __threaded_polling
    polling_thread.raise_exceptions()
  File "/root/Amaar_bott/venv/lib/python3.12/site-packages/telebot/util.py", line 111, in raise_exceptions
    raise self.exception_info
  File "/root/Amaar_bott/venv/lib/python3.12/site-packages/telebot/util.py", line 93, in run
    task(*args, **kwargs)
  File "/root/Amaar_bott/venv/lib/python3.12/site-packages/telebot/__init__.py", line 688, in __retrieve_updates
    updates = self.get_updates(offset=(self.last_update_id + 1),
             ^^^^^^^^^^^^^^^^^^^^^^^^^^^^^^^^^^^^^^^^^^^^^^^^^^
  File "/root/Amaar_bott/venv/lib/python3.12/site-packages/telebot/__init__.py", line 660, in get_updates
    json_updates = apihelper.get_updates(
                   ^^^^^^^^^^^^^^^^^^^^^^
  File "/root/Amaar_bott/venv/lib/python3.12/site-packages/telebot/apihelper.py", line 330, in get_updates
    return _make_request(token, method_url, params=payload)
           ^^^^^^^^^^^^^^^^^^^^^^^^^^^^^^^^^^^^^^^^^^^^^^^^
  File "/root/Amaar_bott/venv/lib/python3.12/site-packages/telebot/apihelper.py", line 168, in _make_request
    json_result = _check_result(method_name, result)
                  ^^^^^^^^^^^^^^^^^^^^^^^^^^^^^^^^^^
  File "/root/Amaar_bott/venv/lib/python3.12/site-packages/telebot/apihelper.py", line 195, in _check_result
    raise ApiTelegramException(method_name, result, result_json)
telebot.apihelper.ApiTelegramException: A request to the Telegram API was unsuccessful. Error code: 409. Description: Conflict: terminated by other getUpdates request; make sure that only one bot instance is running
"
2024-11-04 13:28:25,015 (__init__.py:1241 MainThread) ERROR - TeleBot: "Threaded polling exception: A request to the Telegram API was unsuccessful. Error code: 409. Description: Conflict: terminated by other getUpdates request; make sure that only one bot instance is running"
2024-11-04 13:28:25,016 (__init__.py:1243 MainThread) ERROR - TeleBot: "Exception traceback:
Traceback (most recent call last):
  File "/root/Amaar_bott/venv/lib/python3.12/site-packages/telebot/__init__.py", line 1234, in __threaded_polling
    polling_thread.raise_exceptions()
  File "/root/Amaar_bott/venv/lib/python3.12/site-packages/telebot/util.py", line 111, in raise_exceptions
    raise self.exception_info
  File "/root/Amaar_bott/venv/lib/python3.12/site-packages/telebot/util.py", line 93, in run
    task(*args, **kwargs)
  File "/root/Amaar_bott/venv/lib/python3.12/site-packages/telebot/__init__.py", line 688, in __retrieve_updates
    updates = self.get_updates(offset=(self.last_update_id + 1),
             ^^^^^^^^^^^^^^^^^^^^^^^^^^^^^^^^^^^^^^^^^^^^^^^^^^
  File "/root/Amaar_bott/venv/lib/python3.12/site-packages/telebot/__init__.py", line 660, in get_updates
    json_updates = apihelper.get_updates(
                   ^^^^^^^^^^^^^^^^^^^^^^
  File "/root/Amaar_bott/venv/lib/python3.12/site-packages/telebot/apihelper.py", line 330, in get_updates
    return _make_request(token, method_url, params=payload)
           ^^^^^^^^^^^^^^^^^^^^^^^^^^^^^^^^^^^^^^^^^^^^^^^^
  File "/root/Amaar_bott/venv/lib/python3.12/site-packages/telebot/apihelper.py", line 168, in _make_request
    json_result = _check_result(method_name, result)
                  ^^^^^^^^^^^^^^^^^^^^^^^^^^^^^^^^^^
  File "/root/Amaar_bott/venv/lib/python3.12/site-packages/telebot/apihelper.py", line 195, in _check_result
    raise ApiTelegramException(method_name, result, result_json)
telebot.apihelper.ApiTelegramException: A request to the Telegram API was unsuccessful. Error code: 409. Description: Conflict: terminated by other getUpdates request; make sure that only one bot instance is running
"
2024-11-05 05:11:23,652 (__init__.py:1241 MainThread) ERROR - TeleBot: "Threaded polling exception: A request to the Telegram API was unsuccessful. Error code: 409. Description: Conflict: terminated by other getUpdates request; make sure that only one bot instance is running"
2024-11-05 05:11:23,653 (__init__.py:1243 MainThread) ERROR - TeleBot: "Exception traceback:
Traceback (most recent call last):
  File "/root/Amaar_bott/venv/lib/python3.12/site-packages/telebot/__init__.py", line 1234, in __threaded_polling
    polling_thread.raise_exceptions()
  File "/root/Amaar_bott/venv/lib/python3.12/site-packages/telebot/util.py", line 111, in raise_exceptions
    raise self.exception_info
  File "/root/Amaar_bott/venv/lib/python3.12/site-packages/telebot/util.py", line 93, in run
    task(*args, **kwargs)
  File "/root/Amaar_bott/venv/lib/python3.12/site-packages/telebot/__init__.py", line 688, in __retrieve_updates
    updates = self.get_updates(offset=(self.last_update_id + 1),
             ^^^^^^^^^^^^^^^^^^^^^^^^^^^^^^^^^^^^^^^^^^^^^^^^^^
  File "/root/Amaar_bott/venv/lib/python3.12/site-packages/telebot/__init__.py", line 660, in get_updates
    json_updates = apihelper.get_updates(
                   ^^^^^^^^^^^^^^^^^^^^^^
  File "/root/Amaar_bott/venv/lib/python3.12/site-packages/telebot/apihelper.py", line 330, in get_updates
    return _make_request(token, method_url, params=payload)
           ^^^^^^^^^^^^^^^^^^^^^^^^^^^^^^^^^^^^^^^^^^^^^^^^
  File "/root/Amaar_bott/venv/lib/python3.12/site-packages/telebot/apihelper.py", line 168, in _make_request
    json_result = _check_result(method_name, result)
                  ^^^^^^^^^^^^^^^^^^^^^^^^^^^^^^^^^^
  File "/root/Amaar_bott/venv/lib/python3.12/site-packages/telebot/apihelper.py", line 195, in _check_result
    raise ApiTelegramException(method_name, result, result_json)
telebot.apihelper.ApiTelegramException: A request to the Telegram API was unsuccessful. Error code: 409. Description: Conflict: terminated by other getUpdates request; make sure that only one bot instance is running
"
2024-11-05 05:11:27,241 (__init__.py:1241 MainThread) ERROR - TeleBot: "Threaded polling exception: A request to the Telegram API was unsuccessful. Error code: 409. Description: Conflict: terminated by other getUpdates request; make sure that only one bot instance is running"
2024-11-05 05:11:27,242 (__init__.py:1243 MainThread) ERROR - TeleBot: "Exception traceback:
Traceback (most recent call last):
  File "/root/Amaar_bott/venv/lib/python3.12/site-packages/telebot/__init__.py", line 1234, in __threaded_polling
    polling_thread.raise_exceptions()
  File "/root/Amaar_bott/venv/lib/python3.12/site-packages/telebot/util.py", line 111, in raise_exceptions
    raise self.exception_info
  File "/root/Amaar_bott/venv/lib/python3.12/site-packages/telebot/util.py", line 93, in run
    task(*args, **kwargs)
  File "/root/Amaar_bott/venv/lib/python3.12/site-packages/telebot/__init__.py", line 688, in __retrieve_updates
    updates = self.get_updates(offset=(self.last_update_id + 1),
             ^^^^^^^^^^^^^^^^^^^^^^^^^^^^^^^^^^^^^^^^^^^^^^^^^^
  File "/root/Amaar_bott/venv/lib/python3.12/site-packages/telebot/__init__.py", line 660, in get_updates
    json_updates = apihelper.get_updates(
                   ^^^^^^^^^^^^^^^^^^^^^^
  File "/root/Amaar_bott/venv/lib/python3.12/site-packages/telebot/apihelper.py", line 330, in get_updates
    return _make_request(token, method_url, params=payload)
           ^^^^^^^^^^^^^^^^^^^^^^^^^^^^^^^^^^^^^^^^^^^^^^^^
  File "/root/Amaar_bott/venv/lib/python3.12/site-packages/telebot/apihelper.py", line 168, in _make_request
    json_result = _check_result(method_name, result)
                  ^^^^^^^^^^^^^^^^^^^^^^^^^^^^^^^^^^
  File "/root/Amaar_bott/venv/lib/python3.12/site-packages/telebot/apihelper.py", line 195, in _check_result
    raise ApiTelegramException(method_name, result, result_json)
telebot.apihelper.ApiTelegramException: A request to the Telegram API was unsuccessful. Error code: 409. Description: Conflict: terminated by other getUpdates request; make sure that only one bot instance is running
"
2024-11-05 05:11:31,289 (__init__.py:1241 MainThread) ERROR - TeleBot: "Threaded polling exception: A request to the Telegram API was unsuccessful. Error code: 409. Description: Conflict: terminated by other getUpdates request; make sure that only one bot instance is running"
2024-11-05 05:11:31,290 (__init__.py:1243 MainThread) ERROR - TeleBot: "Exception traceback:
Traceback (most recent call last):
  File "/root/Amaar_bott/venv/lib/python3.12/site-packages/telebot/__init__.py", line 1234, in __threaded_polling
    polling_thread.raise_exceptions()
  File "/root/Amaar_bott/venv/lib/python3.12/site-packages/telebot/util.py", line 111, in raise_exceptions
    raise self.exception_info
  File "/root/Amaar_bott/venv/lib/python3.12/site-packages/telebot/util.py", line 93, in run
    task(*args, **kwargs)
  File "/root/Amaar_bott/venv/lib/python3.12/site-packages/telebot/__init__.py", line 688, in __retrieve_updates
    updates = self.get_updates(offset=(self.last_update_id + 1),
             ^^^^^^^^^^^^^^^^^^^^^^^^^^^^^^^^^^^^^^^^^^^^^^^^^^
  File "/root/Amaar_bott/venv/lib/python3.12/site-packages/telebot/__init__.py", line 660, in get_updates
    json_updates = apihelper.get_updates(
                   ^^^^^^^^^^^^^^^^^^^^^^
  File "/root/Amaar_bott/venv/lib/python3.12/site-packages/telebot/apihelper.py", line 330, in get_updates
    return _make_request(token, method_url, params=payload)
           ^^^^^^^^^^^^^^^^^^^^^^^^^^^^^^^^^^^^^^^^^^^^^^^^
  File "/root/Amaar_bott/venv/lib/python3.12/site-packages/telebot/apihelper.py", line 168, in _make_request
    json_result = _check_result(method_name, result)
                  ^^^^^^^^^^^^^^^^^^^^^^^^^^^^^^^^^^
  File "/root/Amaar_bott/venv/lib/python3.12/site-packages/telebot/apihelper.py", line 195, in _check_result
    raise ApiTelegramException(method_name, result, result_json)
telebot.apihelper.ApiTelegramException: A request to the Telegram API was unsuccessful. Error code: 409. Description: Conflict: terminated by other getUpdates request; make sure that only one bot instance is running
"
2024-11-05 05:11:36,333 (__init__.py:1241 MainThread) ERROR - TeleBot: "Threaded polling exception: A request to the Telegram API was unsuccessful. Error code: 409. Description: Conflict: terminated by other getUpdates request; make sure that only one bot instance is running"
2024-11-05 05:11:36,334 (__init__.py:1243 MainThread) ERROR - TeleBot: "Exception traceback:
Traceback (most recent call last):
  File "/root/Amaar_bott/venv/lib/python3.12/site-packages/telebot/__init__.py", line 1234, in __threaded_polling
    polling_thread.raise_exceptions()
  File "/root/Amaar_bott/venv/lib/python3.12/site-packages/telebot/util.py", line 111, in raise_exceptions
    raise self.exception_info
  File "/root/Amaar_bott/venv/lib/python3.12/site-packages/telebot/util.py", line 93, in run
    task(*args, **kwargs)
  File "/root/Amaar_bott/venv/lib/python3.12/site-packages/telebot/__init__.py", line 688, in __retrieve_updates
    updates = self.get_updates(offset=(self.last_update_id + 1),
             ^^^^^^^^^^^^^^^^^^^^^^^^^^^^^^^^^^^^^^^^^^^^^^^^^^
  File "/root/Amaar_bott/venv/lib/python3.12/site-packages/telebot/__init__.py", line 660, in get_updates
    json_updates = apihelper.get_updates(
                   ^^^^^^^^^^^^^^^^^^^^^^
  File "/root/Amaar_bott/venv/lib/python3.12/site-packages/telebot/apihelper.py", line 330, in get_updates
    return _make_request(token, method_url, params=payload)
           ^^^^^^^^^^^^^^^^^^^^^^^^^^^^^^^^^^^^^^^^^^^^^^^^
  File "/root/Amaar_bott/venv/lib/python3.12/site-packages/telebot/apihelper.py", line 168, in _make_request
    json_result = _check_result(method_name, result)
                  ^^^^^^^^^^^^^^^^^^^^^^^^^^^^^^^^^^
  File "/root/Amaar_bott/venv/lib/python3.12/site-packages/telebot/apihelper.py", line 195, in _check_result
    raise ApiTelegramException(method_name, result, result_json)
telebot.apihelper.ApiTelegramException: A request to the Telegram API was unsuccessful. Error code: 409. Description: Conflict: terminated by other getUpdates request; make sure that only one bot instance is running
"
2024-11-05 05:11:41,615 (__init__.py:1241 MainThread) ERROR - TeleBot: "Threaded polling exception: A request to the Telegram API was unsuccessful. Error code: 409. Description: Conflict: terminated by other getUpdates request; make sure that only one bot instance is running"
2024-11-05 05:11:41,616 (__init__.py:1243 MainThread) ERROR - TeleBot: "Exception traceback:
Traceback (most recent call last):
  File "/root/Amaar_bott/venv/lib/python3.12/site-packages/telebot/__init__.py", line 1234, in __threaded_polling
    polling_thread.raise_exceptions()
  File "/root/Amaar_bott/venv/lib/python3.12/site-packages/telebot/util.py", line 111, in raise_exceptions
    raise self.exception_info
  File "/root/Amaar_bott/venv/lib/python3.12/site-packages/telebot/util.py", line 93, in run
    task(*args, **kwargs)
  File "/root/Amaar_bott/venv/lib/python3.12/site-packages/telebot/__init__.py", line 688, in __retrieve_updates
    updates = self.get_updates(offset=(self.last_update_id + 1),
             ^^^^^^^^^^^^^^^^^^^^^^^^^^^^^^^^^^^^^^^^^^^^^^^^^^
  File "/root/Amaar_bott/venv/lib/python3.12/site-packages/telebot/__init__.py", line 660, in get_updates
    json_updates = apihelper.get_updates(
                   ^^^^^^^^^^^^^^^^^^^^^^
  File "/root/Amaar_bott/venv/lib/python3.12/site-packages/telebot/apihelper.py", line 330, in get_updates
    return _make_request(token, method_url, params=payload)
           ^^^^^^^^^^^^^^^^^^^^^^^^^^^^^^^^^^^^^^^^^^^^^^^^
  File "/root/Amaar_bott/venv/lib/python3.12/site-packages/telebot/apihelper.py", line 168, in _make_request
    json_result = _check_result(method_name, result)
                  ^^^^^^^^^^^^^^^^^^^^^^^^^^^^^^^^^^
  File "/root/Amaar_bott/venv/lib/python3.12/site-packages/telebot/apihelper.py", line 195, in _check_result
    raise ApiTelegramException(method_name, result, result_json)
telebot.apihelper.ApiTelegramException: A request to the Telegram API was unsuccessful. Error code: 409. Description: Conflict: terminated by other getUpdates request; make sure that only one bot instance is running
"
2024-11-05 05:11:48,933 (__init__.py:1241 MainThread) ERROR - TeleBot: "Threaded polling exception: A request to the Telegram API was unsuccessful. Error code: 409. Description: Conflict: terminated by other getUpdates request; make sure that only one bot instance is running"
2024-11-05 05:11:48,934 (__init__.py:1243 MainThread) ERROR - TeleBot: "Exception traceback:
Traceback (most recent call last):
  File "/root/Amaar_bott/venv/lib/python3.12/site-packages/telebot/__init__.py", line 1234, in __threaded_polling
    polling_thread.raise_exceptions()
  File "/root/Amaar_bott/venv/lib/python3.12/site-packages/telebot/util.py", line 111, in raise_exceptions
    raise self.exception_info
  File "/root/Amaar_bott/venv/lib/python3.12/site-packages/telebot/util.py", line 93, in run
    task(*args, **kwargs)
  File "/root/Amaar_bott/venv/lib/python3.12/site-packages/telebot/__init__.py", line 688, in __retrieve_updates
    updates = self.get_updates(offset=(self.last_update_id + 1),
             ^^^^^^^^^^^^^^^^^^^^^^^^^^^^^^^^^^^^^^^^^^^^^^^^^^
  File "/root/Amaar_bott/venv/lib/python3.12/site-packages/telebot/__init__.py", line 660, in get_updates
    json_updates = apihelper.get_updates(
                   ^^^^^^^^^^^^^^^^^^^^^^
  File "/root/Amaar_bott/venv/lib/python3.12/site-packages/telebot/apihelper.py", line 330, in get_updates
    return _make_request(token, method_url, params=payload)
           ^^^^^^^^^^^^^^^^^^^^^^^^^^^^^^^^^^^^^^^^^^^^^^^^
  File "/root/Amaar_bott/venv/lib/python3.12/site-packages/telebot/apihelper.py", line 168, in _make_request
    json_result = _check_result(method_name, result)
                  ^^^^^^^^^^^^^^^^^^^^^^^^^^^^^^^^^^
  File "/root/Amaar_bott/venv/lib/python3.12/site-packages/telebot/apihelper.py", line 195, in _check_result
    raise ApiTelegramException(method_name, result, result_json)
telebot.apihelper.ApiTelegramException: A request to the Telegram API was unsuccessful. Error code: 409. Description: Conflict: terminated by other getUpdates request; make sure that only one bot instance is running
"
2024-11-05 05:12:00,512 (__init__.py:1241 MainThread) ERROR - TeleBot: "Threaded polling exception: A request to the Telegram API was unsuccessful. Error code: 409. Description: Conflict: terminated by other getUpdates request; make sure that only one bot instance is running"
2024-11-05 05:12:00,513 (__init__.py:1243 MainThread) ERROR - TeleBot: "Exception traceback:
Traceback (most recent call last):
  File "/root/Amaar_bott/venv/lib/python3.12/site-packages/telebot/__init__.py", line 1234, in __threaded_polling
    polling_thread.raise_exceptions()
  File "/root/Amaar_bott/venv/lib/python3.12/site-packages/telebot/util.py", line 111, in raise_exceptions
    raise self.exception_info
  File "/root/Amaar_bott/venv/lib/python3.12/site-packages/telebot/util.py", line 93, in run
    task(*args, **kwargs)
  File "/root/Amaar_bott/venv/lib/python3.12/site-packages/telebot/__init__.py", line 688, in __retrieve_updates
    updates = self.get_updates(offset=(self.last_update_id + 1),
             ^^^^^^^^^^^^^^^^^^^^^^^^^^^^^^^^^^^^^^^^^^^^^^^^^^
  File "/root/Amaar_bott/venv/lib/python3.12/site-packages/telebot/__init__.py", line 660, in get_updates
    json_updates = apihelper.get_updates(
                   ^^^^^^^^^^^^^^^^^^^^^^
  File "/root/Amaar_bott/venv/lib/python3.12/site-packages/telebot/apihelper.py", line 330, in get_updates
    return _make_request(token, method_url, params=payload)
           ^^^^^^^^^^^^^^^^^^^^^^^^^^^^^^^^^^^^^^^^^^^^^^^^
  File "/root/Amaar_bott/venv/lib/python3.12/site-packages/telebot/apihelper.py", line 168, in _make_request
    json_result = _check_result(method_name, result)
                  ^^^^^^^^^^^^^^^^^^^^^^^^^^^^^^^^^^
  File "/root/Amaar_bott/venv/lib/python3.12/site-packages/telebot/apihelper.py", line 195, in _check_result
    raise ApiTelegramException(method_name, result, result_json)
telebot.apihelper.ApiTelegramException: A request to the Telegram API was unsuccessful. Error code: 409. Description: Conflict: terminated by other getUpdates request; make sure that only one bot instance is running
"
2024-11-05 05:12:20,612 (__init__.py:1241 MainThread) ERROR - TeleBot: "Threaded polling exception: A request to the Telegram API was unsuccessful. Error code: 409. Description: Conflict: terminated by other getUpdates request; make sure that only one bot instance is running"
2024-11-05 05:12:20,613 (__init__.py:1243 MainThread) ERROR - TeleBot: "Exception traceback:
Traceback (most recent call last):
  File "/root/Amaar_bott/venv/lib/python3.12/site-packages/telebot/__init__.py", line 1234, in __threaded_polling
    polling_thread.raise_exceptions()
  File "/root/Amaar_bott/venv/lib/python3.12/site-packages/telebot/util.py", line 111, in raise_exceptions
    raise self.exception_info
  File "/root/Amaar_bott/venv/lib/python3.12/site-packages/telebot/util.py", line 93, in run
    task(*args, **kwargs)
  File "/root/Amaar_bott/venv/lib/python3.12/site-packages/telebot/__init__.py", line 688, in __retrieve_updates
    updates = self.get_updates(offset=(self.last_update_id + 1),
             ^^^^^^^^^^^^^^^^^^^^^^^^^^^^^^^^^^^^^^^^^^^^^^^^^^
  File "/root/Amaar_bott/venv/lib/python3.12/site-packages/telebot/__init__.py", line 660, in get_updates
    json_updates = apihelper.get_updates(
                   ^^^^^^^^^^^^^^^^^^^^^^
  File "/root/Amaar_bott/venv/lib/python3.12/site-packages/telebot/apihelper.py", line 330, in get_updates
    return _make_request(token, method_url, params=payload)
           ^^^^^^^^^^^^^^^^^^^^^^^^^^^^^^^^^^^^^^^^^^^^^^^^
  File "/root/Amaar_bott/venv/lib/python3.12/site-packages/telebot/apihelper.py", line 168, in _make_request
    json_result = _check_result(method_name, result)
                  ^^^^^^^^^^^^^^^^^^^^^^^^^^^^^^^^^^
  File "/root/Amaar_bott/venv/lib/python3.12/site-packages/telebot/apihelper.py", line 195, in _check_result
    raise ApiTelegramException(method_name, result, result_json)
telebot.apihelper.ApiTelegramException: A request to the Telegram API was unsuccessful. Error code: 409. Description: Conflict: terminated by other getUpdates request; make sure that only one bot instance is running
"
2024-11-05 05:12:57,671 (__init__.py:1241 MainThread) ERROR - TeleBot: "Threaded polling exception: A request to the Telegram API was unsuccessful. Error code: 409. Description: Conflict: terminated by other getUpdates request; make sure that only one bot instance is running"
2024-11-05 05:12:57,671 (__init__.py:1243 MainThread) ERROR - TeleBot: "Exception traceback:
Traceback (most recent call last):
  File "/root/Amaar_bott/venv/lib/python3.12/site-packages/telebot/__init__.py", line 1234, in __threaded_polling
    polling_thread.raise_exceptions()
  File "/root/Amaar_bott/venv/lib/python3.12/site-packages/telebot/util.py", line 111, in raise_exceptions
    raise self.exception_info
  File "/root/Amaar_bott/venv/lib/python3.12/site-packages/telebot/util.py", line 93, in run
    task(*args, **kwargs)
  File "/root/Amaar_bott/venv/lib/python3.12/site-packages/telebot/__init__.py", line 688, in __retrieve_updates
    updates = self.get_updates(offset=(self.last_update_id + 1),
             ^^^^^^^^^^^^^^^^^^^^^^^^^^^^^^^^^^^^^^^^^^^^^^^^^^
  File "/root/Amaar_bott/venv/lib/python3.12/site-packages/telebot/__init__.py", line 660, in get_updates
    json_updates = apihelper.get_updates(
                   ^^^^^^^^^^^^^^^^^^^^^^
  File "/root/Amaar_bott/venv/lib/python3.12/site-packages/telebot/apihelper.py", line 330, in get_updates
    return _make_request(token, method_url, params=payload)
           ^^^^^^^^^^^^^^^^^^^^^^^^^^^^^^^^^^^^^^^^^^^^^^^^
  File "/root/Amaar_bott/venv/lib/python3.12/site-packages/telebot/apihelper.py", line 168, in _make_request
    json_result = _check_result(method_name, result)
                  ^^^^^^^^^^^^^^^^^^^^^^^^^^^^^^^^^^
  File "/root/Amaar_bott/venv/lib/python3.12/site-packages/telebot/apihelper.py", line 195, in _check_result
    raise ApiTelegramException(method_name, result, result_json)
telebot.apihelper.ApiTelegramException: A request to the Telegram API was unsuccessful. Error code: 409. Description: Conflict: terminated by other getUpdates request; make sure that only one bot instance is running
"
2024-11-05 05:14:00,991 (__init__.py:1241 MainThread) ERROR - TeleBot: "Threaded polling exception: A request to the Telegram API was unsuccessful. Error code: 409. Description: Conflict: terminated by other getUpdates request; make sure that only one bot instance is running"
2024-11-05 05:14:00,991 (__init__.py:1243 MainThread) ERROR - TeleBot: "Exception traceback:
Traceback (most recent call last):
  File "/root/Amaar_bott/venv/lib/python3.12/site-packages/telebot/__init__.py", line 1234, in __threaded_polling
    polling_thread.raise_exceptions()
  File "/root/Amaar_bott/venv/lib/python3.12/site-packages/telebot/util.py", line 111, in raise_exceptions
    raise self.exception_info
  File "/root/Amaar_bott/venv/lib/python3.12/site-packages/telebot/util.py", line 93, in run
    task(*args, **kwargs)
  File "/root/Amaar_bott/venv/lib/python3.12/site-packages/telebot/__init__.py", line 688, in __retrieve_updates
    updates = self.get_updates(offset=(self.last_update_id + 1),
             ^^^^^^^^^^^^^^^^^^^^^^^^^^^^^^^^^^^^^^^^^^^^^^^^^^
  File "/root/Amaar_bott/venv/lib/python3.12/site-packages/telebot/__init__.py", line 660, in get_updates
    json_updates = apihelper.get_updates(
                   ^^^^^^^^^^^^^^^^^^^^^^
  File "/root/Amaar_bott/venv/lib/python3.12/site-packages/telebot/apihelper.py", line 330, in get_updates
    return _make_request(token, method_url, params=payload)
           ^^^^^^^^^^^^^^^^^^^^^^^^^^^^^^^^^^^^^^^^^^^^^^^^
  File "/root/Amaar_bott/venv/lib/python3.12/site-packages/telebot/apihelper.py", line 168, in _make_request
    json_result = _check_result(method_name, result)
                  ^^^^^^^^^^^^^^^^^^^^^^^^^^^^^^^^^^
  File "/root/Amaar_bott/venv/lib/python3.12/site-packages/telebot/apihelper.py", line 195, in _check_result
    raise ApiTelegramException(method_name, result, result_json)
telebot.apihelper.ApiTelegramException: A request to the Telegram API was unsuccessful. Error code: 409. Description: Conflict: terminated by other getUpdates request; make sure that only one bot instance is running
"
2024-11-11 01:12:27,309 (__init__.py:1241 MainThread) ERROR - TeleBot: "Threaded polling exception: A request to the Telegram API was unsuccessful. Error code: 502. Description: Bad Gateway"
2024-11-11 01:12:27,310 (__init__.py:1243 MainThread) ERROR - TeleBot: "Exception traceback:
Traceback (most recent call last):
  File "/root/Amaar_bott/venv/lib/python3.12/site-packages/telebot/__init__.py", line 1234, in __threaded_polling
    polling_thread.raise_exceptions()
  File "/root/Amaar_bott/venv/lib/python3.12/site-packages/telebot/util.py", line 111, in raise_exceptions
    raise self.exception_info
  File "/root/Amaar_bott/venv/lib/python3.12/site-packages/telebot/util.py", line 93, in run
    task(*args, **kwargs)
  File "/root/Amaar_bott/venv/lib/python3.12/site-packages/telebot/__init__.py", line 688, in __retrieve_updates
    updates = self.get_updates(offset=(self.last_update_id + 1),
             ^^^^^^^^^^^^^^^^^^^^^^^^^^^^^^^^^^^^^^^^^^^^^^^^^^
  File "/root/Amaar_bott/venv/lib/python3.12/site-packages/telebot/__init__.py", line 660, in get_updates
    json_updates = apihelper.get_updates(
                   ^^^^^^^^^^^^^^^^^^^^^^
  File "/root/Amaar_bott/venv/lib/python3.12/site-packages/telebot/apihelper.py", line 330, in get_updates
    return _make_request(token, method_url, params=payload)
           ^^^^^^^^^^^^^^^^^^^^^^^^^^^^^^^^^^^^^^^^^^^^^^^^
  File "/root/Amaar_bott/venv/lib/python3.12/site-packages/telebot/apihelper.py", line 168, in _make_request
    json_result = _check_result(method_name, result)
                  ^^^^^^^^^^^^^^^^^^^^^^^^^^^^^^^^^^
  File "/root/Amaar_bott/venv/lib/python3.12/site-packages/telebot/apihelper.py", line 195, in _check_result
    raise ApiTelegramException(method_name, result, result_json)
telebot.apihelper.ApiTelegramException: A request to the Telegram API was unsuccessful. Error code: 502. Description: Bad Gateway
"
2024-11-11 01:12:27,633 (__init__.py:1241 MainThread) ERROR - TeleBot: "Threaded polling exception: A request to the Telegram API was unsuccessful. Error code: 502. Description: Bad Gateway"
2024-11-11 01:12:27,634 (__init__.py:1243 MainThread) ERROR - TeleBot: "Exception traceback:
Traceback (most recent call last):
  File "/root/Amaar_bott/venv/lib/python3.12/site-packages/telebot/__init__.py", line 1234, in __threaded_polling
    polling_thread.raise_exceptions()
  File "/root/Amaar_bott/venv/lib/python3.12/site-packages/telebot/util.py", line 111, in raise_exceptions
    raise self.exception_info
  File "/root/Amaar_bott/venv/lib/python3.12/site-packages/telebot/util.py", line 93, in run
    task(*args, **kwargs)
  File "/root/Amaar_bott/venv/lib/python3.12/site-packages/telebot/__init__.py", line 688, in __retrieve_updates
    updates = self.get_updates(offset=(self.last_update_id + 1),
             ^^^^^^^^^^^^^^^^^^^^^^^^^^^^^^^^^^^^^^^^^^^^^^^^^^
  File "/root/Amaar_bott/venv/lib/python3.12/site-packages/telebot/__init__.py", line 660, in get_updates
    json_updates = apihelper.get_updates(
                   ^^^^^^^^^^^^^^^^^^^^^^
  File "/root/Amaar_bott/venv/lib/python3.12/site-packages/telebot/apihelper.py", line 330, in get_updates
    return _make_request(token, method_url, params=payload)
           ^^^^^^^^^^^^^^^^^^^^^^^^^^^^^^^^^^^^^^^^^^^^^^^^
  File "/root/Amaar_bott/venv/lib/python3.12/site-packages/telebot/apihelper.py", line 168, in _make_request
    json_result = _check_result(method_name, result)
                  ^^^^^^^^^^^^^^^^^^^^^^^^^^^^^^^^^^
  File "/root/Amaar_bott/venv/lib/python3.12/site-packages/telebot/apihelper.py", line 195, in _check_result
    raise ApiTelegramException(method_name, result, result_json)
telebot.apihelper.ApiTelegramException: A request to the Telegram API was unsuccessful. Error code: 502. Description: Bad Gateway
"
2024-11-11 01:12:28,149 (__init__.py:1241 MainThread) ERROR - TeleBot: "Threaded polling exception: A request to the Telegram API was unsuccessful. Error code: 502. Description: Bad Gateway"
2024-11-11 01:12:28,150 (__init__.py:1243 MainThread) ERROR - TeleBot: "Exception traceback:
Traceback (most recent call last):
  File "/root/Amaar_bott/venv/lib/python3.12/site-packages/telebot/__init__.py", line 1234, in __threaded_polling
    polling_thread.raise_exceptions()
  File "/root/Amaar_bott/venv/lib/python3.12/site-packages/telebot/util.py", line 111, in raise_exceptions
    raise self.exception_info
  File "/root/Amaar_bott/venv/lib/python3.12/site-packages/telebot/util.py", line 93, in run
    task(*args, **kwargs)
  File "/root/Amaar_bott/venv/lib/python3.12/site-packages/telebot/__init__.py", line 688, in __retrieve_updates
    updates = self.get_updates(offset=(self.last_update_id + 1),
             ^^^^^^^^^^^^^^^^^^^^^^^^^^^^^^^^^^^^^^^^^^^^^^^^^^
  File "/root/Amaar_bott/venv/lib/python3.12/site-packages/telebot/__init__.py", line 660, in get_updates
    json_updates = apihelper.get_updates(
                   ^^^^^^^^^^^^^^^^^^^^^^
  File "/root/Amaar_bott/venv/lib/python3.12/site-packages/telebot/apihelper.py", line 330, in get_updates
    return _make_request(token, method_url, params=payload)
           ^^^^^^^^^^^^^^^^^^^^^^^^^^^^^^^^^^^^^^^^^^^^^^^^
  File "/root/Amaar_bott/venv/lib/python3.12/site-packages/telebot/apihelper.py", line 168, in _make_request
    json_result = _check_result(method_name, result)
                  ^^^^^^^^^^^^^^^^^^^^^^^^^^^^^^^^^^
  File "/root/Amaar_bott/venv/lib/python3.12/site-packages/telebot/apihelper.py", line 195, in _check_result
    raise ApiTelegramException(method_name, result, result_json)
telebot.apihelper.ApiTelegramException: A request to the Telegram API was unsuccessful. Error code: 502. Description: Bad Gateway
"
2024-11-11 01:12:54,158 (__init__.py:1115 MainThread) ERROR - TeleBot: "Infinity polling exception: HTTPSConnectionPool(host='api.telegram.org', port=443): Read timed out. (read timeout=25)"
2024-11-11 01:12:54,160 (__init__.py:1117 MainThread) ERROR - TeleBot: "Exception traceback:
Traceback (most recent call last):
  File "/root/Amaar_bott/venv/lib/python3.12/site-packages/urllib3/connectionpool.py", line 536, in _make_request
    response = conn.getresponse()
               ^^^^^^^^^^^^^^^^^^
  File "/root/Amaar_bott/venv/lib/python3.12/site-packages/urllib3/connection.py", line 507, in getresponse
    httplib_response = super().getresponse()
                       ^^^^^^^^^^^^^^^^^^^^^
  File "/usr/lib/python3.12/http/client.py", line 1428, in getresponse
    response.begin()
  File "/usr/lib/python3.12/http/client.py", line 331, in begin
    version, status, reason = self._read_status()
                              ^^^^^^^^^^^^^^^^^^^
  File "/usr/lib/python3.12/http/client.py", line 292, in _read_status
    line = str(self.fp.readline(_MAXLINE + 1), "iso-8859-1")
               ^^^^^^^^^^^^^^^^^^^^^^^^^^^^^^
  File "/usr/lib/python3.12/socket.py", line 720, in readinto
    return self._sock.recv_into(b)
           ^^^^^^^^^^^^^^^^^^^^^^^
  File "/usr/lib/python3.12/ssl.py", line 1251, in recv_into
    return self.read(nbytes, buffer)
           ^^^^^^^^^^^^^^^^^^^^^^^^^
  File "/usr/lib/python3.12/ssl.py", line 1103, in read
    return self._sslobj.read(len, buffer)
           ^^^^^^^^^^^^^^^^^^^^^^^^^^^^^^
TimeoutError: The read operation timed out

The above exception was the direct cause of the following exception:

Traceback (most recent call last):
  File "/root/Amaar_bott/venv/lib/python3.12/site-packages/requests/adapters.py", line 667, in send
    resp = conn.urlopen(
           ^^^^^^^^^^^^^
  File "/root/Amaar_bott/venv/lib/python3.12/site-packages/urllib3/connectionpool.py", line 843, in urlopen
    retries = retries.increment(
              ^^^^^^^^^^^^^^^^^^
  File "/root/Amaar_bott/venv/lib/python3.12/site-packages/urllib3/util/retry.py", line 474, in increment
    raise reraise(type(error), error, _stacktrace)
          ^^^^^^^^^^^^^^^^^^^^^^^^^^^^^^^^^^^^^^^^
  File "/root/Amaar_bott/venv/lib/python3.12/site-packages/urllib3/util/util.py", line 39, in reraise
    raise value
  File "/root/Amaar_bott/venv/lib/python3.12/site-packages/urllib3/connectionpool.py", line 789, in urlopen
    response = self._make_request(
               ^^^^^^^^^^^^^^^^^^^
  File "/root/Amaar_bott/venv/lib/python3.12/site-packages/urllib3/connectionpool.py", line 538, in _make_request
    self._raise_timeout(err=e, url=url, timeout_value=read_timeout)
  File "/root/Amaar_bott/venv/lib/python3.12/site-packages/urllib3/connectionpool.py", line 369, in _raise_timeout
    raise ReadTimeoutError(
urllib3.exceptions.ReadTimeoutError: HTTPSConnectionPool(host='api.telegram.org', port=443): Read timed out. (read timeout=25)

During handling of the above exception, another exception occurred:

Traceback (most recent call last):
  File "/root/Amaar_bott/venv/lib/python3.12/site-packages/telebot/__init__.py", line 1110, in infinity_polling
    self.polling(non_stop=True, timeout=timeout, long_polling_timeout=long_polling_timeout,
  File "/root/Amaar_bott/venv/lib/python3.12/site-packages/telebot/__init__.py", line 1198, in polling
    self.__threaded_polling(non_stop=non_stop, interval=interval, timeout=timeout, long_polling_timeout=long_polling_timeout,
  File "/root/Amaar_bott/venv/lib/python3.12/site-packages/telebot/__init__.py", line 1273, in __threaded_polling
    raise e
  File "/root/Amaar_bott/venv/lib/python3.12/site-packages/telebot/__init__.py", line 1234, in __threaded_polling
    polling_thread.raise_exceptions()
  File "/root/Amaar_bott/venv/lib/python3.12/site-packages/telebot/util.py", line 111, in raise_exceptions
    raise self.exception_info
  File "/root/Amaar_bott/venv/lib/python3.12/site-packages/telebot/util.py", line 93, in run
    task(*args, **kwargs)
  File "/root/Amaar_bott/venv/lib/python3.12/site-packages/telebot/__init__.py", line 688, in __retrieve_updates
    updates = self.get_updates(offset=(self.last_update_id + 1),
             ^^^^^^^^^^^^^^^^^^^^^^^^^^^^^^^^^^^^^^^^^^^^^^^^^^
  File "/root/Amaar_bott/venv/lib/python3.12/site-packages/telebot/__init__.py", line 660, in get_updates
    json_updates = apihelper.get_updates(
                   ^^^^^^^^^^^^^^^^^^^^^^
  File "/root/Amaar_bott/venv/lib/python3.12/site-packages/telebot/apihelper.py", line 330, in get_updates
    return _make_request(token, method_url, params=payload)
           ^^^^^^^^^^^^^^^^^^^^^^^^^^^^^^^^^^^^^^^^^^^^^^^^
  File "/root/Amaar_bott/venv/lib/python3.12/site-packages/telebot/apihelper.py", line 162, in _make_request
    result = _get_req_session().request(
             ^^^^^^^^^^^^^^^^^^^^^^^^^^^
  File "/root/Amaar_bott/venv/lib/python3.12/site-packages/requests/sessions.py", line 589, in request
    resp = self.send(prep, **send_kwargs)
           ^^^^^^^^^^^^^^^^^^^^^^^^^^^^^^
  File "/root/Amaar_bott/venv/lib/python3.12/site-packages/requests/sessions.py", line 703, in send
    r = adapter.send(request, **kwargs)
        ^^^^^^^^^^^^^^^^^^^^^^^^^^^^^^^
  File "/root/Amaar_bott/venv/lib/python3.12/site-packages/requests/adapters.py", line 713, in send
    raise ReadTimeout(e, request=request)
requests.exceptions.ReadTimeout: HTTPSConnectionPool(host='api.telegram.org', port=443): Read timed out. (read timeout=25)
"
2024-11-11 01:13:22,220 (__init__.py:1115 MainThread) ERROR - TeleBot: "Infinity polling exception: HTTPSConnectionPool(host='api.telegram.org', port=443): Read timed out. (read timeout=25)"
2024-11-11 01:13:22,224 (__init__.py:1117 MainThread) ERROR - TeleBot: "Exception traceback:
Traceback (most recent call last):
  File "/root/Amaar_bott/venv/lib/python3.12/site-packages/urllib3/connectionpool.py", line 536, in _make_request
    response = conn.getresponse()
               ^^^^^^^^^^^^^^^^^^
  File "/root/Amaar_bott/venv/lib/python3.12/site-packages/urllib3/connection.py", line 507, in getresponse
    httplib_response = super().getresponse()
                       ^^^^^^^^^^^^^^^^^^^^^
  File "/usr/lib/python3.12/http/client.py", line 1428, in getresponse
    response.begin()
  File "/usr/lib/python3.12/http/client.py", line 331, in begin
    version, status, reason = self._read_status()
                              ^^^^^^^^^^^^^^^^^^^
  File "/usr/lib/python3.12/http/client.py", line 292, in _read_status
    line = str(self.fp.readline(_MAXLINE + 1), "iso-8859-1")
               ^^^^^^^^^^^^^^^^^^^^^^^^^^^^^^
  File "/usr/lib/python3.12/socket.py", line 720, in readinto
    return self._sock.recv_into(b)
           ^^^^^^^^^^^^^^^^^^^^^^^
  File "/usr/lib/python3.12/ssl.py", line 1251, in recv_into
    return self.read(nbytes, buffer)
           ^^^^^^^^^^^^^^^^^^^^^^^^^
  File "/usr/lib/python3.12/ssl.py", line 1103, in read
    return self._sslobj.read(len, buffer)
           ^^^^^^^^^^^^^^^^^^^^^^^^^^^^^^
TimeoutError: The read operation timed out

The above exception was the direct cause of the following exception:

Traceback (most recent call last):
  File "/root/Amaar_bott/venv/lib/python3.12/site-packages/requests/adapters.py", line 667, in send
    resp = conn.urlopen(
           ^^^^^^^^^^^^^
  File "/root/Amaar_bott/venv/lib/python3.12/site-packages/urllib3/connectionpool.py", line 843, in urlopen
    retries = retries.increment(
              ^^^^^^^^^^^^^^^^^^
  File "/root/Amaar_bott/venv/lib/python3.12/site-packages/urllib3/util/retry.py", line 474, in increment
    raise reraise(type(error), error, _stacktrace)
          ^^^^^^^^^^^^^^^^^^^^^^^^^^^^^^^^^^^^^^^^
  File "/root/Amaar_bott/venv/lib/python3.12/site-packages/urllib3/util/util.py", line 39, in reraise
    raise value
  File "/root/Amaar_bott/venv/lib/python3.12/site-packages/urllib3/connectionpool.py", line 789, in urlopen
    response = self._make_request(
               ^^^^^^^^^^^^^^^^^^^
  File "/root/Amaar_bott/venv/lib/python3.12/site-packages/urllib3/connectionpool.py", line 538, in _make_request
    self._raise_timeout(err=e, url=url, timeout_value=read_timeout)
  File "/root/Amaar_bott/venv/lib/python3.12/site-packages/urllib3/connectionpool.py", line 369, in _raise_timeout
    raise ReadTimeoutError(
urllib3.exceptions.ReadTimeoutError: HTTPSConnectionPool(host='api.telegram.org', port=443): Read timed out. (read timeout=25)

During handling of the above exception, another exception occurred:

Traceback (most recent call last):
  File "/root/Amaar_bott/venv/lib/python3.12/site-packages/telebot/__init__.py", line 1110, in infinity_polling
    self.polling(non_stop=True, timeout=timeout, long_polling_timeout=long_polling_timeout,
  File "/root/Amaar_bott/venv/lib/python3.12/site-packages/telebot/__init__.py", line 1198, in polling
    self.__threaded_polling(non_stop=non_stop, interval=interval, timeout=timeout, long_polling_timeout=long_polling_timeout,
  File "/root/Amaar_bott/venv/lib/python3.12/site-packages/telebot/__init__.py", line 1273, in __threaded_polling
    raise e
  File "/root/Amaar_bott/venv/lib/python3.12/site-packages/telebot/__init__.py", line 1234, in __threaded_polling
    polling_thread.raise_exceptions()
  File "/root/Amaar_bott/venv/lib/python3.12/site-packages/telebot/util.py", line 111, in raise_exceptions
    raise self.exception_info
  File "/root/Amaar_bott/venv/lib/python3.12/site-packages/telebot/util.py", line 93, in run
    task(*args, **kwargs)
  File "/root/Amaar_bott/venv/lib/python3.12/site-packages/telebot/__init__.py", line 688, in __retrieve_updates
    updates = self.get_updates(offset=(self.last_update_id + 1),
             ^^^^^^^^^^^^^^^^^^^^^^^^^^^^^^^^^^^^^^^^^^^^^^^^^^
  File "/root/Amaar_bott/venv/lib/python3.12/site-packages/telebot/__init__.py", line 660, in get_updates
    json_updates = apihelper.get_updates(
                   ^^^^^^^^^^^^^^^^^^^^^^
  File "/root/Amaar_bott/venv/lib/python3.12/site-packages/telebot/apihelper.py", line 330, in get_updates
    return _make_request(token, method_url, params=payload)
           ^^^^^^^^^^^^^^^^^^^^^^^^^^^^^^^^^^^^^^^^^^^^^^^^
  File "/root/Amaar_bott/venv/lib/python3.12/site-packages/telebot/apihelper.py", line 162, in _make_request
    result = _get_req_session().request(
             ^^^^^^^^^^^^^^^^^^^^^^^^^^^
  File "/root/Amaar_bott/venv/lib/python3.12/site-packages/requests/sessions.py", line 589, in request
    resp = self.send(prep, **send_kwargs)
           ^^^^^^^^^^^^^^^^^^^^^^^^^^^^^^
  File "/root/Amaar_bott/venv/lib/python3.12/site-packages/requests/sessions.py", line 703, in send
    r = adapter.send(request, **kwargs)
        ^^^^^^^^^^^^^^^^^^^^^^^^^^^^^^^
  File "/root/Amaar_bott/venv/lib/python3.12/site-packages/requests/adapters.py", line 713, in send
    raise ReadTimeout(e, request=request)
requests.exceptions.ReadTimeout: HTTPSConnectionPool(host='api.telegram.org', port=443): Read timed out. (read timeout=25)
"
2024-11-11 01:13:50,291 (__init__.py:1115 MainThread) ERROR - TeleBot: "Infinity polling exception: HTTPSConnectionPool(host='api.telegram.org', port=443): Read timed out. (read timeout=25)"
2024-11-11 01:13:50,295 (__init__.py:1117 MainThread) ERROR - TeleBot: "Exception traceback:
Traceback (most recent call last):
  File "/root/Amaar_bott/venv/lib/python3.12/site-packages/urllib3/connectionpool.py", line 536, in _make_request
    response = conn.getresponse()
               ^^^^^^^^^^^^^^^^^^
  File "/root/Amaar_bott/venv/lib/python3.12/site-packages/urllib3/connection.py", line 507, in getresponse
    httplib_response = super().getresponse()
                       ^^^^^^^^^^^^^^^^^^^^^
  File "/usr/lib/python3.12/http/client.py", line 1428, in getresponse
    response.begin()
  File "/usr/lib/python3.12/http/client.py", line 331, in begin
    version, status, reason = self._read_status()
                              ^^^^^^^^^^^^^^^^^^^
  File "/usr/lib/python3.12/http/client.py", line 292, in _read_status
    line = str(self.fp.readline(_MAXLINE + 1), "iso-8859-1")
               ^^^^^^^^^^^^^^^^^^^^^^^^^^^^^^
  File "/usr/lib/python3.12/socket.py", line 720, in readinto
    return self._sock.recv_into(b)
           ^^^^^^^^^^^^^^^^^^^^^^^
  File "/usr/lib/python3.12/ssl.py", line 1251, in recv_into
    return self.read(nbytes, buffer)
           ^^^^^^^^^^^^^^^^^^^^^^^^^
  File "/usr/lib/python3.12/ssl.py", line 1103, in read
    return self._sslobj.read(len, buffer)
           ^^^^^^^^^^^^^^^^^^^^^^^^^^^^^^
TimeoutError: The read operation timed out

The above exception was the direct cause of the following exception:

Traceback (most recent call last):
  File "/root/Amaar_bott/venv/lib/python3.12/site-packages/requests/adapters.py", line 667, in send
    resp = conn.urlopen(
           ^^^^^^^^^^^^^
  File "/root/Amaar_bott/venv/lib/python3.12/site-packages/urllib3/connectionpool.py", line 843, in urlopen
    retries = retries.increment(
              ^^^^^^^^^^^^^^^^^^
  File "/root/Amaar_bott/venv/lib/python3.12/site-packages/urllib3/util/retry.py", line 474, in increment
    raise reraise(type(error), error, _stacktrace)
          ^^^^^^^^^^^^^^^^^^^^^^^^^^^^^^^^^^^^^^^^
  File "/root/Amaar_bott/venv/lib/python3.12/site-packages/urllib3/util/util.py", line 39, in reraise
    raise value
  File "/root/Amaar_bott/venv/lib/python3.12/site-packages/urllib3/connectionpool.py", line 789, in urlopen
    response = self._make_request(
               ^^^^^^^^^^^^^^^^^^^
  File "/root/Amaar_bott/venv/lib/python3.12/site-packages/urllib3/connectionpool.py", line 538, in _make_request
    self._raise_timeout(err=e, url=url, timeout_value=read_timeout)
  File "/root/Amaar_bott/venv/lib/python3.12/site-packages/urllib3/connectionpool.py", line 369, in _raise_timeout
    raise ReadTimeoutError(
urllib3.exceptions.ReadTimeoutError: HTTPSConnectionPool(host='api.telegram.org', port=443): Read timed out. (read timeout=25)

During handling of the above exception, another exception occurred:

Traceback (most recent call last):
  File "/root/Amaar_bott/venv/lib/python3.12/site-packages/telebot/__init__.py", line 1110, in infinity_polling
    self.polling(non_stop=True, timeout=timeout, long_polling_timeout=long_polling_timeout,
  File "/root/Amaar_bott/venv/lib/python3.12/site-packages/telebot/__init__.py", line 1198, in polling
    self.__threaded_polling(non_stop=non_stop, interval=interval, timeout=timeout, long_polling_timeout=long_polling_timeout,
  File "/root/Amaar_bott/venv/lib/python3.12/site-packages/telebot/__init__.py", line 1273, in __threaded_polling
    raise e
  File "/root/Amaar_bott/venv/lib/python3.12/site-packages/telebot/__init__.py", line 1234, in __threaded_polling
    polling_thread.raise_exceptions()
  File "/root/Amaar_bott/venv/lib/python3.12/site-packages/telebot/util.py", line 111, in raise_exceptions
    raise self.exception_info
  File "/root/Amaar_bott/venv/lib/python3.12/site-packages/telebot/util.py", line 93, in run
    task(*args, **kwargs)
  File "/root/Amaar_bott/venv/lib/python3.12/site-packages/telebot/__init__.py", line 688, in __retrieve_updates
    updates = self.get_updates(offset=(self.last_update_id + 1),
             ^^^^^^^^^^^^^^^^^^^^^^^^^^^^^^^^^^^^^^^^^^^^^^^^^^
  File "/root/Amaar_bott/venv/lib/python3.12/site-packages/telebot/__init__.py", line 660, in get_updates
    json_updates = apihelper.get_updates(
                   ^^^^^^^^^^^^^^^^^^^^^^
  File "/root/Amaar_bott/venv/lib/python3.12/site-packages/telebot/apihelper.py", line 330, in get_updates
    return _make_request(token, method_url, params=payload)
           ^^^^^^^^^^^^^^^^^^^^^^^^^^^^^^^^^^^^^^^^^^^^^^^^
  File "/root/Amaar_bott/venv/lib/python3.12/site-packages/telebot/apihelper.py", line 162, in _make_request
    result = _get_req_session().request(
             ^^^^^^^^^^^^^^^^^^^^^^^^^^^
  File "/root/Amaar_bott/venv/lib/python3.12/site-packages/requests/sessions.py", line 589, in request
    resp = self.send(prep, **send_kwargs)
           ^^^^^^^^^^^^^^^^^^^^^^^^^^^^^^
  File "/root/Amaar_bott/venv/lib/python3.12/site-packages/requests/sessions.py", line 703, in send
    r = adapter.send(request, **kwargs)
        ^^^^^^^^^^^^^^^^^^^^^^^^^^^^^^^
  File "/root/Amaar_bott/venv/lib/python3.12/site-packages/requests/adapters.py", line 713, in send
    raise ReadTimeout(e, request=request)
requests.exceptions.ReadTimeout: HTTPSConnectionPool(host='api.telegram.org', port=443): Read timed out. (read timeout=25)
"
2024-11-12 15:08:52,664 (__init__.py:1241 MainThread) ERROR - TeleBot: "Threaded polling exception: A request to the Telegram API was unsuccessful. Error code: 400. Description: Bad Request: message is not modified: specified new message content and reply markup are exactly the same as a current content and reply markup of the message"
2024-11-12 15:08:52,665 (__init__.py:1243 MainThread) ERROR - TeleBot: "Exception traceback:
Traceback (most recent call last):
  File "/root/Amaar_bott/venv/lib/python3.12/site-packages/telebot/__init__.py", line 1235, in __threaded_polling
    self.worker_pool.raise_exceptions()
  File "/root/Amaar_bott/venv/lib/python3.12/site-packages/telebot/util.py", line 150, in raise_exceptions
    raise self.exception_info
  File "/root/Amaar_bott/venv/lib/python3.12/site-packages/telebot/util.py", line 93, in run
    task(*args, **kwargs)
  File "/root/Amaar_bott/venv/lib/python3.12/site-packages/telebot/__init__.py", line 8945, in _run_middlewares_and_handler
    result = handler['function'](message)
             ^^^^^^^^^^^^^^^^^^^^^^^^^^^^
  File "/root/Amaar_bott/handlers/users/callbacks.py", line 26, in handle_recontacted_callback
    bot.edit_message_text(
  File "/root/Amaar_bott/venv/lib/python3.12/site-packages/telebot/__init__.py", line 4875, in edit_message_text
    result = apihelper.edit_message_text(
             ^^^^^^^^^^^^^^^^^^^^^^^^^^^^
  File "/root/Amaar_bott/venv/lib/python3.12/site-packages/telebot/apihelper.py", line 1465, in edit_message_text
    return _make_request(token, method_url, params=payload, method='post')
           ^^^^^^^^^^^^^^^^^^^^^^^^^^^^^^^^^^^^^^^^^^^^^^^^^^^^^^^^^^^^^^^
  File "/root/Amaar_bott/venv/lib/python3.12/site-packages/telebot/apihelper.py", line 168, in _make_request
    json_result = _check_result(method_name, result)
                  ^^^^^^^^^^^^^^^^^^^^^^^^^^^^^^^^^^
  File "/root/Amaar_bott/venv/lib/python3.12/site-packages/telebot/apihelper.py", line 195, in _check_result
    raise ApiTelegramException(method_name, result, result_json)
telebot.apihelper.ApiTelegramException: A request to the Telegram API was unsuccessful. Error code: 400. Description: Bad Request: message is not modified: specified new message content and reply markup are exactly the same as a current content and reply markup of the message
"
